Workbook

Sheet Wohnflächenberechnung
A1: Wohnflächenberechnung
A2: Ulmer Str. 183, 86156 Augsburg – Stadtvilla, Umbau in 10 WG-Wohnungen + 1 Gewerbeeinheit
A3: Grundlage: Ulmer str Drawings Rev#5 (Plandatum 02.07.2026, Beqiri Bau & Immobilien GmbH, M 1:50)
A5: Geschoss | B5: Einheit | C5: Raum | D5: Fläche (m²) | E5: Bemerkung
A6: EG | B6: WHG 1 | C6: Zimmer 1 | D6: 9
A7: EG | B7: WHG 1 | C7: Zimmer 2 | D7: 12.7
A8: EG | B8: WHG 1 | C8: Zimmer 3 | D8: 11
A9: EG | B9: WHG 1 | C9: Zimmer 4 | D9: 12.82
A10: EG | B10: WHG 1 | C10: Küche | D10: 5.33
A11: EG | B11: WHG 1 | C11: Bad | D11: 3.82
A12: EG | B12: WHG 1 | C12: Flur | D12: 16.5
C13: Summe WHG 1 | D13: =SUM(D6:D12)
A14: EG | B14: WHG 2 | C14: Zimmer 1 | D14: 9.72
A15: EG | B15: WHG 2 | C15: Zimmer 2 | D15: 9.17
A16: EG | B16: WHG 2 | C16: Zimmer 3 | D16: 13.1
A17: EG | B17: WHG 2 | C17: Zimmer 4 | D17: 10.6
A18: EG | B18: WHG 2 | C18: Küche | D18: 4.41
A19: EG | B19: WHG 2 | C19: Bad | D19: 3.06
A20: EG | B20: WHG 2 | C20: Flur | D20: 7.06
C21: Summe WHG 2 | D21: =SUM(D14:D20)
A22: 1.OG | B22: WHG 3 | C22: Zimmer 1 | D22: 10.88
A23: 1.OG | B23: WHG 3 | C23: Zimmer 2 | D23: 9.6
A24: 1.OG | B24: WHG 3 | C24: Zimmer 3 | D24: 9.6
A25: 1.OG | B25: WHG 3 | C25: Zimmer 4 | D25: 9.03
A26: 1.OG | B26: WHG 3 | C26: Küche | D26: 7.23
A27: 1.OG | B27: WHG 3 | C27: Bad | D27: 3.06
A28: 1.OG | B28: WHG 3 | C28: Flur | D28: 7.02
A29: 1.OG | B29: WHG 3 | C29: Balkon (4,38 m², 50 % angerechnet) | D29: 2.19 | E29: WoFlV §4: 50 % von 4,38 m²
C30: Summe WHG 3 | D30: =SUM(D22:D29)
A31: 1.OG | B31: WHG 4 | C31: Zimmer 1 | D31: 10.66
A32: 1.OG | B32: WHG 4 | C32: Zimmer 2 | D32: 11.55
A33: 1.OG | B33: WHG 4 | C33: Zimmer 3 | D33: 10.23
A34: 1.OG | B34: WHG 4 | C34: Küche | D34: 5.8
A35: 1.OG | B35: WHG 4 | C35: Bad | D35: 3.1
A36: 1.OG | B36: WHG 4 | C36: Flur | D36: 6.97
C37: Summe WHG 4 | D37: =SUM(D31:D36)
A38: 1.OG | B38: WHG 5 | C38: Zimmer 1 | D38: 9
A39: 1.OG | B39: WHG 5 | C39: Zimmer 2 | D39: 14.87
A40: 1.OG | B40: WHG 5 | C40: Zimmer 3 | D40: 10.91
A41: 1.OG | B41: WHG 5 | C41: Zimmer 4 | D41: 10.41
...

Sheet Wohnungsliste
A1: Wohnungsliste mit Mietkalkulation (WG-Zimmer, kalt) – FINAL / Stand Rev#5
A2: Ulmer Str. 183, 86156 Augsburg – Vermietung über Coliviq
A4: Miete Zimmer < 10 m² (€/Monat kalt): | D4: 470
A5: Miete Zimmer ≥ 10 m² (€/Monat kalt): | D5: 510
A7: Einheit | B7: Geschoss | C7: Zimmer | D7: Wohnfläche (m²) | E7: Zi. 1 (m²) | F7: Miete Zi. 1 (€) | G7: Zi. 2 (m²) | H7: Miete Zi. 2 (€) | I7: Zi. 3 (m²) | J7: Miete Zi. 3 (€) | K7: Zi. 4 (m²) | L7: Miete Zi. 4 (€) | M7: Kaltmiete gesamt (€/Monat) | N7: Miete (€/m²) | P7: Finale KP | R7: qm Preis | T7: Rendite
A8: WHG 1 | B8: EG | C8: 4 | D8: =Wohnflächenberechnung!D13 | E8: =Wohnflächenberechnung!D6 | F8: =IF(E8<10,$D$4,$D$5) | G8: =Wohnflächenberechnung!D7 | H8: =IF(G8<10,$D$4,$D$5) | I8: =Wohnflächenberechnung!D8 | J8: =IF(I8<10,$D$4,$D$5) | K8: =Wohnflächenberechnung!D9 | L8: =IF(K8<10,$D$4,$D$5) | M8: =SUM(F8,H8,J8,L8) | N8: =M8/D8 | P8: 425700 | R8: =P8/D8 | T8: =M8*12/P8
A9: WHG 2 | B9: EG | C9: 4 | D9: =Wohnflächenberechnung!D21 | E9: =Wohnflächenberechnung!D14 | F9: =IF(E9<10,$D$4,$D$5) | G9: =Wohnflächenberechnung!D15 | H9: =IF(G9<10,$D$4,$D$5) | I9: =Wohnflächenberechnung!D16 | J9: =IF(I9<10,$D$4,$D$5) | K9: =Wohnflächenberechnung!D17 | L9: =IF(K9<10,$D$4,$D$5) | M9: =SUM(F9,H9,J9,L9) | N9: =M9/D9 | P9: 376900 | R9: =P9/D9 | T9: =M9*12/P9
A10: WHG 3 | B10: 1.OG | C10: 4 | D10: =Wohnflächenberechnung!D30 | E10: =Wohnflächenberechnung!D22 | F10: =IF(E10<10,$D$4,$D$5) | G10: =Wohnflächenberechnung!D23 | H10: =IF(G10<10,$D$4,$D$5) | I10: =Wohnflächenberechnung!D24 | J10: =IF(I10<10,$D$4,$D$5) | K10: =Wohnflächenberechnung!D25 | L10: =IF(K10<10,$D$4,$D$5) | M10: =SUM(F10,H10,J10,L10) | N10: =M10/D10 | P10: 383700 | R10: =P10/D10 | T10: =M10*12/P10
A11: WHG 4 | B11: 1.OG | C11: 3 | D11: =Wohnflächenberechnung!D37 | E11: =Wohnflächenberechnung!D31 | F11: =IF(E11<10,$D$4,$D$5) | G11: =Wohnflächenberechnung!D32 | H11: =IF(G11<10,$D$4,$D$5) | I11: =Wohnflächenberechnung!D33 | J11: =IF(I11<10,$D$4,$D$5) | K11: – | L11: – | M11: =SUM(F11,H11,J11,L11) | N11: =M11/D11 | P11: 318800 | R11: =P11/D11 | T11: =M11*12/P11
A12: WHG 5 | B12: 1.OG | C12: 4 | D12: =Wohnflächenberechnung!D45 | E12: =Wohnflächenberechnung!D38 | F12: =IF(E12<10,$D$4,$D$5) | G12: =Wohnflächenberechnung!D39 | H12: =IF(G12<10,$D$4,$D$5) | I12: =Wohnflächenberechnung!D40 | J12: =IF(I12<10,$D$4,$D$5) | K12: =Wohnflächenberechnung!D41 | L12: =IF(K12<10,$D$4,$D$5) | M12: =SUM(F12,H12,J12,L12) | N12: =M12/D12 | P12: 402600 | R12: =P12/D12 | T12: =M12*12/P12
A13: WHG 6 | B13: 2.OG | C13: 4 | D13: =Wohnflächenberechnung!D53 | E13: =Wohnflächenberechnung!D46 | F13: =IF(E13<10,$D$4,$D$5) | G13: =Wohnflächenberechnung!D47 | H13: =IF(G13<10,$D$4,$D$5) | I13: =Wohnflächenberechnung!D48 | J13: =IF(I13<10,$D$4,$D$5) | K13: =Wohnflächenberechnung!D49 | L13: =IF(K13<10,$D$4,$D$5) | M13: =SUM(F13,H13,J13,L13) | N13: =M13/D13 | P13: 372300 | R13: =P13/D13 | T13: =M13*12/P13
A14: WHG 7 | B14: 2.OG | C14: 3 | D14: =Wohnflächenberechnung!D60 | E14: =Wohnflächenberechnung!D54 | F14: =IF(E14<10,$D$4,$D$5) | G14: =Wohnflächenberechnung!D55 | H14: =IF(G14<10,$D$4,$D$5) | I14: =Wohnflächenberechnung!D56 | J14: =IF(I14<10,$D$4,$D$5) | K14: – | L14: – | M14: =SUM(F14,H14,J14,L14) | N14: =M14/D14 | P14: 310700 | R14: =P14/D14 | T14: =M14*12/P14
A15: WHG 8 | B15: 2.OG | C15: 4 | D15: =Wohnflächenberechnung!D68 | E15: =Wohnflächenberechnung!D61 | F15: =IF(E15<10,$D$4,$D$5) | G15: =Wohnflächenberechnung!D62 | H15: =IF(G15<10,$D$4,$D$5) | I15: =Wohnflächenberechnung!D63 | J15: =IF(I15<10,$D$4,$D$5) | K15: =Wohnflächenberechnung!D64 | L15: =IF(K15<10,$D$4,$D$5) | M15: =SUM(F15,H15,J15,L15) | N15: =M15/D15 | P15: 389700 | R15: =P15/D15 | T15: =M15*12/P15
A16: WHG 9 | B16: DG | C16: 4 | D16: =Wohnflächenberechnung!D76 | E16: =Wohnflächenberechnung!D69 | F16: =IF(E16<10,$D$4,$D$5) | G16: =Wohnflächenberechnung!D70 | H16: =IF(G16<10,$D$4,$D$5) | I16: =Wohnflächenberechnung!D71 | J16: =IF(I16<10,$D$4,$D$5) | K16: =Wohnflächenberechnung!D72 | L16: =IF(K16<10,$D$4,$D$5) | M16: =SUM(F16,H16,J16,L16) | N16: =M16/D16 | P16: 399300 | R16: =P16/D16 | T16: =M16*12/P16
A17: WHG 10 | B17: DG | C17: 4 | D17: =Wohnflächenberechnung!D84 | E17: =Wohnflächenberechnung!D77 | F17: =IF(E17<10,$D$4,$D$5) | G17: =Wohnflächenberechnung!D78 | H17: =IF(G17<10,$D$4,$D$5) | I17: =Wohnflächenberechnung!D79 | J17: =IF(I17<10,$D$4,$D$5) | K17: =Wohnflächenberechnung!D80 | L17: =IF(K17<10,$D$4,$D$5) | M17: =SUM(F17,H17,J17,L17) | N17: =M17/D17 | P17: 359300 | R17: =P17/D17 | T17: =M17*12/P17
A18: Gesamt | C18: =SUM(C8:C17) | D18: =SUM(D8:D17) | M18: =SUM(M8:M17) | N18: =M18/D18 | P18: =SUM(P8:P17)
A20: Gewerbeeinheit (EG): 32,20 m² – Laden 17,51 / Ladenzimmer 13,19 / Bad 1,50 m². Kaltmiete Gewerbe: 1.000 €/Monat.
A21: Gesamt-Sollmiete inkl. Gewerbe: 19.660 €/Monat = 235.920 €/Jahr. Summe Einzel-KP WHG 1–10 (ohne Gewerbe): siehe Zeile Gesamt.

Sheet Miteigentumsanteile
A1: Miteigentumsanteile (MEA)
A2: Ulmer Str. 183, 86156 Augsburg – 10 WG-Wohnungen + 1 Gewerbeeinheit
A3: Verteilungsschlüssel: Fläche je Einheit / Gesamtfläche (606,00 m²), gerundet nach Restgrößenverfahren auf ganze 1000stel. Grundlage: WFL-Berechnung Rev#5.
A5: Einheit | B5: Geschoss | C5: Fläche (m²) | D5: Anteil exakt (‰) | E5: MEA (‰)
A6: WHG 1 | B6: EG | C6: 71.17 | D6: 117.44224 | E6: 117
A7: WHG 2 | B7: EG | C7: 57.12 | D7: 94.257426 | E7: 94
A8: WHG 3 | B8: 1.OG | C8: 58.61 | D8: 96.716172 | E8: 97
A9: WHG 4 | B9: 1.OG | C9: 48.31 | D9: 79.719472 | E9: 80
A10: WHG 5 | B10: 1.OG | C10: 61.03 | D10: 100.70957 | E10: 101
A11: WHG 6 | B11: 2.OG | C11: 56.42 | D11: 93.10231 | E11: 93
A12: WHG 7 | B12: 2.OG | C12: 47.08 | D12: 77.689769 | E12: 78
A13: WHG 8 | B13: 2.OG | C13: 59.05 | D13: 97.442244 | E13: 97
A14: WHG 9 | B14: DG | C14: 60.55 | D14: 99.917492 | E14: 100
A15: WHG 10 | B15: DG | C15: 54.46 | D15: 89.867987 | E15: 90
A16: Gewerbe | B16: EG | C16: 32.2 | D16: 53.135314 | E16: 53
A17: Summe | C17: 606 | E17: 1000
